[2024-10-15T09:25:46.093+0000] {taskinstance.py:1165} INFO - Dependencies all met for <TaskInstance: user_processing.create_table manual__2024-10-15T09:25:41+00:00 [queued]>
[2024-10-15T09:25:46.097+0000] {taskinstance.py:1165} INFO - Dependencies all met for <TaskInstance: user_processing.create_table manual__2024-10-15T09:25:41+00:00 [queued]>
[2024-10-15T09:25:46.097+0000] {taskinstance.py:1362} INFO - 
--------------------------------------------------------------------------------
[2024-10-15T09:25:46.097+0000] {taskinstance.py:1363} INFO - Starting attempt 1 of 1
[2024-10-15T09:25:46.097+0000] {taskinstance.py:1364} INFO - 
--------------------------------------------------------------------------------
[2024-10-15T09:25:46.102+0000] {taskinstance.py:1383} INFO - Executing <Task(PostgresOperator): create_table> on 2024-10-15 09:25:41+00:00
[2024-10-15T09:25:46.104+0000] {standard_task_runner.py:55} INFO - Started process 119 to run task
[2024-10-15T09:25:46.106+0000] {standard_task_runner.py:82} INFO - Running: ['***', 'tasks', 'run', 'user_processing', 'create_table', 'manual__2024-10-15T09:25:41+00:00', '--job-id', '8', '--raw', '--subdir', 'DAGS_FOLDER/user_processing.py', '--cfg-path', '/tmp/tmpykc_1mc5']
[2024-10-15T09:25:46.107+0000] {standard_task_runner.py:83} INFO - Job 8: Subtask create_table
[2024-10-15T09:25:46.128+0000] {task_command.py:376} INFO - Running <TaskInstance: user_processing.create_table manual__2024-10-15T09:25:41+00:00 [running]> on host b2abadeb415a
[2024-10-15T09:25:46.152+0000] {taskinstance.py:1592} INFO - Exporting the following env vars:
AIRFLOW_CTX_DAG_OWNER=***
AIRFLOW_CTX_DAG_ID=user_processing
AIRFLOW_CTX_TASK_ID=create_table
AIRFLOW_CTX_EXECUTION_DATE=2024-10-15T09:25:41+00:00
AIRFLOW_CTX_TRY_NUMBER=1
AIRFLOW_CTX_DAG_RUN_ID=manual__2024-10-15T09:25:41+00:00
[2024-10-15T09:25:46.158+0000] {taskinstance.py:1851} ERROR - Task failed with exception
Traceback (most recent call last):
  File "/home/airflow/.local/lib/python3.7/site-packages/airflow/providers/postgres/operators/postgres.py", line 94, in execute
    self.hook.run(self.sql, self.autocommit, parameters=self.parameters)
  File "/home/airflow/.local/lib/python3.7/site-packages/airflow/providers/common/sql/hooks/sql.py", line 288, in run
    with closing(self.get_conn()) as conn:
  File "/home/airflow/.local/lib/python3.7/site-packages/airflow/providers/postgres/hooks/postgres.py", line 88, in get_conn
    conn = deepcopy(self.connection or self.get_connection(conn_id))
  File "/home/airflow/.local/lib/python3.7/site-packages/airflow/hooks/base.py", line 70, in get_connection
    conn = Connection.get_connection_from_secrets(conn_id)
  File "/home/airflow/.local/lib/python3.7/site-packages/airflow/models/connection.py", line 432, in get_connection_from_secrets
    raise AirflowNotFoundException(f"The conn_id `{conn_id}` isn't defined")
airflow.exceptions.AirflowNotFoundException: The conn_id `postgres` isn't defined
[2024-10-15T09:25:46.159+0000] {taskinstance.py:1406} INFO - Marking task as FAILED. dag_id=user_processing, task_id=create_table, execution_date=20241015T092541, start_date=20241015T092546, end_date=20241015T092546
[2024-10-15T09:25:46.163+0000] {standard_task_runner.py:105} ERROR - Failed to execute job 8 for task create_table (The conn_id `postgres` isn't defined; 119)
[2024-10-15T09:25:46.207+0000] {local_task_job.py:164} INFO - Task exited with return code 1
[2024-10-15T09:25:46.220+0000] {local_task_job.py:273} INFO - 0 downstream tasks scheduled from follow-on schedule check
